Workbook

Sheet Detail Pengeluaran
A1: tanggal | B1: kategori | C1: nama barang | D1: qty | E1: satuan | F1: harga | G1: total harga | H1: Column 8 | I1: Column 9 | J1: Column 10 | K1: Column 11 | L1: Column 12 | M1: Column 13 | N1: Column 14 | O1: Column 15 | P1: Column 16 | Q1: Column 17 | R1: Column 18 | S1: Column 19 | T1: Column 20 | U1: Column 21 | V1: Column 22 | W1: Column 23 | X1: Column 24 | Y1: Column 25 | Z1: Column 26 | AA1: Column 27
A2: 46235 | B2: BAR | C2: galon | D2: 1 | F2: 15000 | G2: =F2*D2 -> 15000
A3: 46235 | B3: BAR | C3: kacang | D3: 2 | F3: 23000 | G3: =F3*D3 -> 46000
A4: 46235 | B4: BAR | C4: coklat | D4: 1 | F4: 20000 | G4: =F4*D4 -> 20000
A5: 46235 | B5: KITCHEN | C5: lemon | D5: 3 | F5: 13000 | G5: =F5*D5 -> 39000
A6: 46235 | B6: KITCHEN | C6: yupi | D6: 1 | F6: 20000 | G6: =F6*D6 -> 20000
A7: 46235 | B7: BAKER | C7: CREAMCHEESE | D7: 1 | E7: kg | F7: 90000 | G7: =F7*D7 -> 90000
A8: 46235 | B8: BAKER | C8: gula | D8: 1 | F8: 20000 | G8: =F8*D8 -> 20000
A9: 46235 | B9: BAKER | C9: batu | D9: 1 | F9: 50000 | G9: =F9*D9 -> 50000
A10: 46235 | B10: OPERASIONAL | C10: PASIR | D10: 1 | E10: KARUNG | F10: 10000 | G10: =F10*D10 -> 10000
A12: 46236 | B12: BAR | C12: es batu | D12: 12 | E12: pcs | F12: 15000 | G12: =F12*D12 -> 180000
A13: 46236 | B13: BAR | C13: gula batu | D13: 4 | E13: pcs | F13: 2000 | G13: =F13*D13 -> 8000
A14: 46236 | B14: KITCHEN | C14: madu | D14: 5 | E14: pcs | F14: 4000 | G14: =F14*D14 -> 20000
A15: 46236 | B15: KITCHEN | C15: ayam | D15: 3 | E15: pcs | F15: 89000 | G15: =F15*D15 -> 267000
A16: 46236 | B16: BAKER | C16: salt | D16: 6 | E16: pcs | F16: 89000 | G16: =F16*D16 -> 534000
A17: 46236 | B17: BAKER | C17: salt | D17: 6 | E17: pcs | F17: 89000 | G17: =F17*D17 -> 534000
G18: =F18*D18 -> 0
A19: 46237 | B19: BAR | C19: salt | D19: 5 | E19: pcs | F19: 89000 | G19: =F19*D19 -> 445000
A20: 46237 | B20: BAKER | C20: salt | D20: 6 | E20: pcs | F20: 89000 | G20: =F20*D20 -> 534000
A21: 46237 | B21: BAKER | C21: salt | D21: 6 | E21: pcs | F21: 89000 | G21: =F21*D21 -> 534000
G22: =F22*D22 -> 0
A23: 46238 | B23: BAKER | C23: salt | D23: 6 | E23: pcs | F23: 89000 | G23: =F23*D23 -> 534000
G24: =F24*D24 -> 0
A25: 46239 | B25: BAKER | C25: salt | D25: 6 | E25: pcs | F25: 89000 | G25: =F25*D25 -> 534000
G26: =F26*D26 -> 0
A27: 46240 | B27: BAKER | C27: salt | D27: 6 | E27: pcs | F27: 89000 | G27: =F27*D27 -> 534000
G28: =F28*D28 -> 0
A29: 46241 | B29: BAKER | C29: salt | D29: 6 | E29: pcs | F29: 89000 | G29: =F29*D29 -> 534000
G30: =F30*D30 -> 0
A31: 46242 | B31: BAKER | C31: salt | D31: 6 | E31: pcs | F31: 89000 | G31: =F31*D31 -> 534000
A32: 46243 | B32: BAKER | C32: salt | D32: 6 | E32: pcs | F32: 89000 | G32: =F32*D32 -> 534000
A33: 46244 | B33: OPERASIONAL | C33: babi | D33: 1 | E33: pcs | F33: 200000 | G33: =F33*D33 -> 200000
A34: 46237 | G34: =F34*D34 -> 0
A35: 46237 | G35: =F35*D35 -> 0
A36: 46238 | G36: =F36*D36 -> 0
A37: 46239 | G37: =F37*D37 -> 0
A38: 46240 | G38: =F38*D38 -> 0
A39: 46241 | G39: =F39*D39 -> 0
A40: 46242 | G40: =F40*D40 -> 0
A41: 46243 | G41: =F41*D41 -> 0
...

Sheet Total pengeluaran

Sheet Transaksi by
A1: HASIL AKHIR PENGELUARAN DAN PENDAPATAN
A4: TANGGAL | B4: QRIS | C4: DEBIT | D4: CASH | E4: TOTAL
A5: 46235 | B5: 500000 | C5: 500000 | D5: 500000 | E5: =SUM(B5:D5) -> 1500000
A6: 46236 | B6: 50000 | C6: 50000 | D6: 4000000 | E6: =SUM(B6:D6) -> 4100000
E7: =SUM(B7:D7) -> 0
E8: =SUM(B8:D8) -> 0
E9: =SUM(B9:D9) -> 0
E10: =SUM(B10:D10) -> 0
B11: =SUM(TRANSAKSI_BY[QRIS]) -> 550000 | C11: =SUM(TRANSAKSI_BY[DEBIT]) -> 550000 | D11: =SUM(TRANSAKSI_BY[CASH]) -> 4500000 | E11: =SUM(TRANSAKSI_BY[TOTAL]) -> 5600000

Sheet Hasil akhir
A3: TANGGAL | B3: PENDAPATAN | E3: TOTAL PENDAPATAN | F3: TOTAL PENGELUARAN | G3: TOTAL BERSIH
B4: BAR | C4: KITCHEN | D4: BAKER
A5: 46235 | B5: 500000 | C5: 600000 | D5: 400000 | E5: =B5+C5+D5 -> 1500000 | F5: ='Total pengeluaran'!C8 -> 310000 | G5: =E5-F5 -> 1190000
A6: 46236 | B6: 1300000 | C6: 1500000 | D6: 1300000 | E6: =B6+C6+D6 -> 4100000 | F6: ='Total pengeluaran'!D8 -> 1543000 | G6: =E6-F6 -> 2557000
A7: 46237 | B7: 0 | C7: 0 | D7: 0 | E7: =B7+C7+D7 -> 0 | F7: ='Total pengeluaran'!E8 -> 1513000 | G7: =E7-F7 -> -1513000
A8: 46238 | E8: =B8+C8+D8 -> 0 | F8: ='Total pengeluaran'!F8 -> 534000
A9: 46239 | E9: =B9+C9+D9 -> 0 | F9: ='Total pengeluaran'!G8 -> 534000
A10: 46240 | E10: =B10+C10+D10 -> 0
A11: 46241 | E11: =B11+C11+D11 -> 0
A12: 46242 | E12: =B12+C12+D12 -> 0
A13: 46243 | E13: =B13+C13+D13 -> 0
A14: 46244 | E14: =B14+C14+D14 -> 0
A15: 46245 | E15: =B15+C15+D15 -> 0
A16: 46246 | E16: =B16+C16+D16 -> 0
A17: 46247 | E17: =B17+C17+D17 -> 0
A18: 46248 | E18: =B18+C18+D18 -> 0
A19: 46249 | E19: =B19+C19+D19 -> 0
A20: 46250 | E20: =B20+C20+D20 -> 0
A21: 46251 | E21: =B21+C21+D21 -> 0
... A35: 46265 | E35: =B35+C35+D35 -> 0
A36: TOTAL | B36: =SUM(B5:B35) -> 1800000 | C36: =SUM(C5:C35) -> 2100000 | D36: =SUM(D5:D35) -> 1700000 | E36: =SUM(E5:E35) -> 5600000 | F36: =SUM(F5:F35) -> 4434000 | G36: =SUM(G5:G35) -> 2234000

Sheet Tabungan
A1: TABUNGAN
A4: TANGGAL | B4: BARANG | C4: QTY | D4: SATUAN | E4: TOTAL | F4: TOTAL HARGA | H4: TANGGAL | I4: MASUK | J4: KELUAR | K4: TOTAL
A5: 46234 | B5: KURSI | C5: 12 | D5: BUAH | E5: 100000 | F5: =E5*C5 -> 1200000 | H5: 46234 | I5: 5000000 | J5: =F5 -> 1200000 | K5: =I5-J5 -> 3800000
A6: 46236 | B6: PLAFON | C6: 1 | D6: BUAH | E6: 3000000 | F6: =E6*C6 -> 3000000 | H6: 46236 | I6: 0 | J6: =F6 -> 3000000 | K6: =I6-J6 -> -3000000
F7: =SUM(KAS_KELUAR[TOTAL HARGA]) -> 4200000 | K7: =TABUNGAN[MASUK]-TABUNGAN[KELUAR] -> 0
K8: =SUM(TABUNGAN[TOTAL]) -> 800000

Sheet Keuangan sewa
A2: BULAN | B2: UANG MASUK | C2: PELUNASAN | D2: TRF
A3: JANUARI | B3: 29400000
F4: RUMUS
F5: Pengeluaran di (+) uang sewa (-) pendapatan
